Workbook

Sheet Sheet1
A1: Column1 | B1: GDP_CVM
A2: 1993 | B2: =SUM(B3:B6) -> 4341027
A3: Q1 | B3: 1067301
A4: Q2 | B4: 1039924
A5: Q3 | B5: 1086494
A6: Q4 | B6: 1147308
A7: 1994 | B7: =SUM(B8:B11) -> 4688180
A8: Q1 | B8: 1179517
A9: Q2 | B9: 1146232
A10: Q3 | B10: 1135828
A11: Q4 | B11: 1226603
A12: 1995 | B12: =SUM(B13:B16) -> 5068875
A13: Q1 | B13: 1265610
A14: Q2 | B14: 1256367
A15: Q3 | B15: 1231962
A16: Q4 | B16: 1314936
A17: 1996 | B17: =SUM(B18:B21) -> 5355365
A18: Q1 | B18: 1313862
A19: Q2 | B19: 1336374
A20: Q3 | B20: 1323012
A21: Q4 | B21: 1382117
A22: 1997 | B22: =SUM(B23:B26) -> 5207901
A23: Q1 | B23: 1318993
A24: Q2 | B24: 1309139
A25: Q3 | B25: 1282881
A26: Q4 | B26: 1296888
A27: 1998 | B27: =SUM(B28:B31) -> 4810328
A28: Q1 | B28: 1244216
A29: Q2 | B29: 1145060
A30: Q3 | B30: 1155997
A31: Q4 | B31: 1265055
A32: 1999 | B32: =SUM(B33:B36) -> 5030271
A33: Q1 | B33: 1259716
A34: Q2 | B34: 1206997
A35: Q3 | B35: 1246015
A36: Q4 | B36: 1317543
A37: 2000 | B37: =SUM(B38:B41) -> 5254382
A38: Q1 | B38: 1346757
A39: Q2 | B39: 1279194
A40: Q3 | B40: 1276273
...

Sheet Sheet3
A1: 1147308 | C1: 1067301
A2: 1226603 | B2: =AVERAGE(A1:A32) -> 2019901.1 | C2: 1039924 | D2: =AVERAGE(C1:C128) -> 1946876.5
A3: 1314936 | C3: 1086494
A4: 1382117 | C4: 1147308
A5: 1296888 | C5: 1179517
A6: 1265055 | C6: 1146232
A7: 1317543 | C7: 1135828
A8: 1352158 | C8: 1226603
A9: 1407869 | C9: 1265610
A10: 1503042 | C10: 1256367
A11: 1622511 | C11: 1231962
A12: 1730192 | C12: 1314936
A13: 1796955 | C13: 1313862
A14: 1893689 | C14: 1336374
... A32: 2918940 | C32: 1352158
C33: 1378078
C34: 1326723
C35: 1322686
C36: 1407869
C37: 1441030
C38: 1411214
C39: 1414291
C40: 1503042
C41: 1550742
C42: 1500109
C43: 1511005
C44: 1622511
... C128: 2918940

Sheet Sheet2
A1: Column1 | B1: GDP_CVM | C1: GDP_seasonally | D1: quarter average | E1: seasonal index | F1: seasonally adjusted
A2: Q1 | B2: 1067301 | C2: 1043940 | D2: 2001961.2 | E2: =Table2[[#This Row],[quarter average]]/Sheet3!$D$2 -> 1.0282939 | F2: =Table2[[#This Row],[GDP_CVM]]/Table2[[#This Row],[seasonal index]] -> 1037933.8
A3: Q2 | B3: 1039924 | C3: 1051493 | D3: 1888174.5 | E3: =Table2[[#This Row],[quarter average]]/Sheet3!$D$2 -> 0.96984808 | F3: =Table2[[#This Row],[GDP_CVM]]/Table2[[#This Row],[seasonal index]] -> 1072254.5
A4: Q3 | B4: 1086494 | C4: 1117265 | D4: 1877469.4 | E4: =Table2[[#This Row],[quarter average]]/Sheet3!$D$2 -> 0.96434947 | F4: =Table2[[#This Row],[GDP_CVM]]/Table2[[#This Row],[seasonal index]] -> 1126660
A5: Q4 | B5: 1147308 | C5: 1128004 | D5: 2019901.1 | E5: =Table2[[#This Row],[quarter average]]/Sheet3!$D$2 -> 1.0375086 | F5: =Table2[[#This Row],[GDP_CVM]]/Table2[[#This Row],[seasonal index]] -> 1105829.9
A6: Q1 | B6: 1179517 | C6: 1155167 | D6: 2001961.2 | E6: =Table2[[#This Row],[quarter average]]/Sheet3!$D$2 -> 1.0282939 | F6: =Table2[[#This Row],[GDP_CVM]]/Table2[[#This Row],[seasonal index]] -> 1147062.2
A7: Q2 | B7: 1146232 | C7: 1159212 | D7: 1888174.5 | E7: =Table2[[#This Row],[quarter average]]/Sheet3!$D$2 -> 0.96984808 | F7: =Table2[[#This Row],[GDP_CVM]]/Table2[[#This Row],[seasonal index]] -> 1181867.6
A8: Q3 | B8: 1135828 | C8: 1167189 | D8: 1877469.4 | E8: =Table2[[#This Row],[quarter average]]/Sheet3!$D$2 -> 0.96434947 | F8: =Table2[[#This Row],[GDP_CVM]]/Table2[[#This Row],[seasonal index]] -> 1177817.8
A9: Q4 | B9: 1226603 | C9: 1204635 | D9: 2019901.1 | E9: =Table2[[#This Row],[quarter average]]/Sheet3!$D$2 -> 1.0375086 | F9: =Table2[[#This Row],[GDP_CVM]]/Table2[[#This Row],[seasonal index]] -> 1182258.2
A10: Q1 | B10: 1265610 | C10: 1241364 | D10: 2001961.2 | E10: =Table2[[#This Row],[quarter average]]/Sheet3!$D$2 -> 1.0282939 | F10: =Table2[[#This Row],[GDP_CVM]]/Table2[[#This Row],[seasonal index]] -> 1230786.3
A11: Q2 | B11: 1256367 | C11: 1271334 | D11: 1888174.5 | E11: =Table2[[#This Row],[quarter average]]/Sheet3!$D$2 -> 0.96984808 | F11: =Table2[[#This Row],[GDP_CVM]]/Table2[[#This Row],[seasonal index]] -> 1295426.6
A12: Q3 | B12: 1231962 | C12: 1266064 | D12: 1877469.4 | E12: =Table2[[#This Row],[quarter average]]/Sheet3!$D$2 -> 0.96434947 | F12: =Table2[[#This Row],[GDP_CVM]]/Table2[[#This Row],[seasonal index]] -> 1277505.8
A13: Q4 | B13: 1314936 | C13: 1287811 | D13: 2019901.1 | E13: =Table2[[#This Row],[quarter average]]/Sheet3!$D$2 -> 1.0375086 | F13: =Table2[[#This Row],[GDP_CVM]]/Table2[[#This Row],[seasonal index]] -> 1267397.7
... A129: Q4 | B129: 2918940 | C129: 2824464 | D129: 2019901.1 | E129: =Table2[[#This Row],[quarter average]]/Sheet3!$D$2 -> 1.0375086 | F129: =Table2[[#This Row],[GDP_CVM]]/Table2[[#This Row],[seasonal index]] -> 2813412.9
