Workbook

Sheet 2B5CQPQ1
A1: Quarterly Gross Domestic Product Series by Industry, Q1 1981 to Q1 2024
B3: At Constant 2018 Prices
B4: 2000 | F4: 2001 | J4: 2002 | N4: 2003 | R4: 2004 | V4: 2005 | Z4: 2006 | AD4: 2007 | AH4: 2008 | AL4: 2009 | AP4: 2010 | AT4: 2011 | AX4: 2012 | BB4: 2013 | BF4: 2014 | BJ4: 2015 | BN4: 2016 | BR4: 2017 | BV4: 2018 | BZ4: 2019 | CD4: 2020 | CH4: 2021 | CL4: 2022 | CP4: 2023 | CT4: 2024
B5: Q1 | C5: Q2 | D5: Q3 | E5: Q4 | F5: Q1 | G5: Q2 | H5: Q3 | I5: Q4 | J5: Q1 | K5: Q2 | L5: Q3 | M5: Q4 | N5: Q1 | O5: Q2 | P5: Q3 | Q5: Q4 | R5: Q1 | S5: Q2 | T5: Q3 | U5: Q4 | V5: Q1 | W5: Q2 | X5: Q3 | Y5: Q4 | Z5: Q1 | AA5: Q2 | AB5: Q3 | AC5: Q4 | AD5: Q1 | AE5: Q2 | AF5: Q3 | AG5: Q4 | AH5: Q1 | AI5: Q2 | AJ5: Q3 | AK5: Q4 | AL5: Q1 | AM5: Q2 | AN5: Q3 | AO5: Q4 | AP5: Q1 | AQ5: Q2 | AR5: Q3 | AS5: Q4 | AT5: Q1 | AU5: Q2 | AV5: Q3 | AW5: Q4 | AX5: Q1 | AY5: Q2 | AZ5: Q3 | BA5: Q4 | BB5: Q1 | BC5: Q2 | BD5: Q3 | BE5: Q4 | BF5: Q1 | BG5: Q2 | BH5: Q3 | BI5: Q4 | BJ5: Q1 | BK5: Q2 | BL5: Q3 | BM5: Q4 | BN5: Q1 | BO5: Q2 | BP5: Q3 | BQ5: Q4 | BR5: Q1 | BS5: Q2 | BT5: Q3 | BU5: Q4 | BV5: Q1 | BW5: Q2 | BX5: Q3 | BY5: Q4 | BZ5: Q1 | CA5: Q2 | CB5: Q3 | CC5: Q4 | CD5: Q1 | CE5: Q2 | CF5: Q3 | CG5: Q4 | CH5: Q1 | CI5: Q2 | CJ5: Q3 | CK5: Q4 | CL5: Q1 | CM5: Q2 | CN5: Q3 | CO5: Q4 | CP5: Q1 | CQ5: Q2 | CR5: Q3 | CS5: Q4 | CT5: Q1 | CU5: Q2 | CV5: Q3 | CW5: Q4
A6: Gross Domestic Product | B6: 1653296 | C6: 1729789 | D6: 1709413 | E6: 1892885 | F6: 1693209 | G6: 1786322 | H6: 1762583 | I6: 1956269 | J6: 1758847 | K6: 1851705 | L6: 1809767 | M6: 2045575 | N6: 1840079 | O6: 1932976 | P6: 1909701 | Q6: 2162922 | R6: 1972128 | S6: 2077812 | T6: 2029119 | U6: 2282020 | V6: 2071140 | W6: 2195369 | X6: 2117985 | Y6: 2389831 | Z6: 2164381 | AA6: 2325314 | AB6: 2217593 | AC6: 2533516 | AD6: 2297797 | AE6: 2484417 | AF6: 2362773 | AG6: 2698252 | AH6: 2393607 | AI6: 2602999 | AJ6: 2491196 | AK6: 2783075 | AL6: 2420350 | AM6: 2652251 | AN6: 2514311 | AO6: 2832721 | AP6: 2616891 | AQ6: 2863767 | AR6: 2692052 | AS6: 3011152 | AT6: 2743209 | AU6: 2965726 | AV6: 2773776 | AW6: 3132649 | AX6: 2908899 | AY6: 3150174 | AZ6: 2979022 | BA6: 3378370 | BB6: 3129776 | BC6: 3386829 | BD6: 3178884 | BE6: 3559155 | BF6: 3308136 | BG6: 3621756 | BH6: 3367553 | BI6: 3798601 | BJ6: 3481796 | BK6: 3853504 | BL6: 3589388 | BM6: 4066219 | BN6: 3722688 | BO6: 4140186 | BP6: 3852483 | BQ6: 4347319 | BR6: 3959977 | BS6: 4437331 | BT6: 4142636 | BU6: 4636033 | BV6: 4215576 | BW6: 4720384 | BX6: 4397241 | BY6: 4931988 | BZ6: 4463186 | CA6: 4985924 | CB6: 4675544 | CC6: 5258096 | CD6: 4433805 | CE6: 4142943 | CF6: 4135499 | CG6: 4825596 | CH6: 4266797 | CI6: 4641825 | CJ6: 4426630 | CK6: 5204832 | CL6: 4611219 | CM6: 4990934 | CN6: 4767549 | CO6: 5575902 | CP6: 4907013 | CQ6: 5203455 | CR6: 5051396 | CS6: 5884528 | CT6: 5195588 | CU6: 5539083 | CV6: 5316054 | CW6: 6193631
A9: Latest update:
A10: 20250403 10:00
A12: Source:
A13: Philippine Statistics Authority (PSA)
A15: Contact:
A16: Anthony B. Abalos
A17: Officer-in-Charge
A18: Expenditure and Integrated Accounts Division
A19: Philippine Statistics Authority
A20: 21st Floor, PSA Headquarters, PSA Complex East Avenue, Diliman, Quezon City
A21: a.abalos@psa.gov.ph
A24: Units:
... A36: 2B5CQPQ1

Sheet Sheet1
A1: year | B1: quarter | C1: RGDP | D1: quarter average | E1: seasonal index | F1: seasonally adjusted
A2: 2000 | B2: Q1 | C2: 1653296 | D2: 3129175.6 | E2: =Table1[[#This Row],[quarter average]]/Sheet2!$D$1 -> 0.93642066 | F2: =Table1[[#This Row],[RGDP]]/Table1[[#This Row],[seasonal index]] -> 1765548.4
B3: Q2 | C3: 1729789 | D3: 3371311 | E3: =Table1[[#This Row],[quarter average]]/Sheet2!$D$1 -> 1.0088808 | F3: =Table1[[#This Row],[RGDP]]/Table1[[#This Row],[seasonal index]] -> 1714562.3
B4: Q3 | C4: 1709413 | D4: 3210805.9 | E4: =Table1[[#This Row],[quarter average]]/Sheet2!$D$1 -> 0.96084893 | F4: =Table1[[#This Row],[RGDP]]/Table1[[#This Row],[seasonal index]] -> 1779065.3
B5: Q4 | C5: 1892885 | D5: 3655245.5 | E5: =Table1[[#This Row],[quarter average]]/Sheet2!$D$1 -> 1.0938496 | F5: =Table1[[#This Row],[RGDP]]/Table1[[#This Row],[seasonal index]] -> 1730480.2
A6: 2001 | B6: Q1 | C6: 1693209 | D6: 3129175.6 | E6: =Table1[[#This Row],[quarter average]]/Sheet2!$D$1 -> 0.93642066 | F6: =Table1[[#This Row],[RGDP]]/Table1[[#This Row],[seasonal index]] -> 1808171.3
B7: Q2 | C7: 1786322 | D7: 3371311 | E7: =Table1[[#This Row],[quarter average]]/Sheet2!$D$1 -> 1.0088808 | F7: =Table1[[#This Row],[RGDP]]/Table1[[#This Row],[seasonal index]] -> 1770597.6
B8: Q3 | C8: 1762583 | D8: 3210805.9 | E8: =Table1[[#This Row],[quarter average]]/Sheet2!$D$1 -> 0.96084893 | F8: =Table1[[#This Row],[RGDP]]/Table1[[#This Row],[seasonal index]] -> 1834401.8
B9: Q4 | C9: 1956269 | D9: 3655245.5 | E9: =Table1[[#This Row],[quarter average]]/Sheet2!$D$1 -> 1.0938496 | F9: =Table1[[#This Row],[RGDP]]/Table1[[#This Row],[seasonal index]] -> 1788426
A10: 2002 | B10: Q1 | C10: 1758847 | D10: 3129175.6 | E10: =Table1[[#This Row],[quarter average]]/Sheet2!$D$1 -> 0.93642066 | F10: =Table1[[#This Row],[RGDP]]/Table1[[#This Row],[seasonal index]] -> 1878265.9
B11: Q2 | C11: 1851705 | D11: 3371311 | E11: =Table1[[#This Row],[quarter average]]/Sheet2!$D$1 -> 1.0088808 | F11: =Table1[[#This Row],[RGDP]]/Table1[[#This Row],[seasonal index]] -> 1835405.1
B12: Q3 | C12: 1809767 | D12: 3210805.9 | E12: =Table1[[#This Row],[quarter average]]/Sheet2!$D$1 -> 0.96084893 | F12: =Table1[[#This Row],[RGDP]]/Table1[[#This Row],[seasonal index]] -> 1883508.4
B13: Q4 | C13: 2045575 | D13: 3655245.5 | E13: =Table1[[#This Row],[quarter average]]/Sheet2!$D$1 -> 1.0938496 | F13: =Table1[[#This Row],[RGDP]]/Table1[[#This Row],[seasonal index]] -> 1870069.7
A14: 2003 | B14: Q1 | C14: 1840079 | D14: 3129175.6 | E14: =Table1[[#This Row],[quarter average]]/Sheet2!$D$1 -> 0.93642066 | F14: =Table1[[#This Row],[RGDP]]/Table1[[#This Row],[seasonal index]] -> 1965013.2
B15: Q2 | C15: 1932976 | D15: 3371311 | E15: =Table1[[#This Row],[quarter average]]/Sheet2!$D$1 -> 1.0088808 | F15: =Table1[[#This Row],[RGDP]]/Table1[[#This Row],[seasonal index]] -> 1915960.7
B16: Q3 | C16: 1909701 | D16: 3210805.9 | E16: =Table1[[#This Row],[quarter average]]/Sheet2!$D$1 -> 0.96084893 | F16: =Table1[[#This Row],[RGDP]]/Table1[[#This Row],[seasonal index]] -> 1987514.3
B17: Q4 | C17: 2162922 | D17: 3655245.5 | E17: =Table1[[#This Row],[quarter average]]/Sheet2!$D$1 -> 1.0938496 | F17: =Table1[[#This Row],[RGDP]]/Table1[[#This Row],[seasonal index]] -> 1977348.7
A18: 2004 | B18: Q1 | C18: 1972128 | D18: 3129175.6 | E18: =Table1[[#This Row],[quarter average]]/Sheet2!$D$1 -> 0.93642066 | F18: =Table1[[#This Row],[RGDP]]/Table1[[#This Row],[seasonal index]] -> 2106027.9
B19: Q2 | C19: 2077812 | D19: 3371311 | E19: =Table1[[#This Row],[quarter average]]/Sheet2!$D$1 -> 1.0088808 | F19: =Table1[[#This Row],[RGDP]]/Table1[[#This Row],[seasonal index]] -> 2059521.7
B20: Q3 | C20: 2029119 | D20: 3210805.9 | E20: =Table1[[#This Row],[quarter average]]/Sheet2!$D$1 -> 0.96084893 | F20: =Table1[[#This Row],[RGDP]]/Table1[[#This Row],[seasonal index]] -> 2111798.2
B21: Q4 | C21: 2282020 | D21: 3655245.5 | E21: =Table1[[#This Row],[quarter average]]/Sheet2!$D$1 -> 1.0938496 | F21: =Table1[[#This Row],[RGDP]]/Table1[[#This Row],[seasonal index]] -> 2086228.4
A22: 2005 | B22: Q1 | C22: 2071140 | D22: 3129175.6 | E22: =Table1[[#This Row],[quarter average]]/Sheet2!$D$1 -> 0.93642066 | F22: =Table1[[#This Row],[RGDP]]/Table1[[#This Row],[seasonal index]] -> 2211762.4
B23: Q2 | C23: 2195369 | D23: 3371311 | E23: =Table1[[#This Row],[quarter average]]/Sheet2!$D$1 -> 1.0088808 | F23: =Table1[[#This Row],[RGDP]]/Table1[[#This Row],[seasonal index]] -> 2176043.9
B24: Q3 | C24: 2117985 | D24: 3210805.9 | E24: =Table1[[#This Row],[quarter average]]/Sheet2!$D$1 -> 0.96084893 | F24: =Table1[[#This Row],[RGDP]]/Table1[[#This Row],[seasonal index]] -> 2204285.1
B25: Q4 | C25: 2389831 | D25: 3655245.5 | E25: =Table1[[#This Row],[quarter average]]/Sheet2!$D$1 -> 1.0938496 | F25: =Table1[[#This Row],[RGDP]]/Table1[[#This Row],[seasonal index]] -> 2184789.4
A26: 2006 | B26: Q1 | C26: 2164381 | D26: 3129175.6 | E26: =Table1[[#This Row],[quarter average]]/Sheet2!$D$1 -> 0.93642066 | F26: =Table1[[#This Row],[RGDP]]/Table1[[#This Row],[seasonal index]] -> 2311334.1
B27: Q2 | C27: 2325314 | D27: 3371311 | E27: =Table1[[#This Row],[quarter average]]/Sheet2!$D$1 -> 1.0088808 | F27: =Table1[[#This Row],[RGDP]]/Table1[[#This Row],[seasonal index]] -> 2304845.1
B28: Q3 | C28: 2217593 | D28: 3210805.9 | E28: =Table1[[#This Row],[quarter average]]/Sheet2!$D$1 -> 0.96084893 | F28: =Table1[[#This Row],[RGDP]]/Table1[[#This Row],[seasonal index]] -> 2307951.8
B29: Q4 | C29: 2533516 | D29: 3655245.5 | E29: =Table1[[#This Row],[quarter average]]/Sheet2!$D$1 -> 1.0938496 | F29: =Table1[[#This Row],[RGDP]]/Table1[[#This Row],[seasonal index]] -> 2316146.6
A30: 2007 | B30: Q1 | C30: 2297797 | D30: 3129175.6 | E30: =Table1[[#This Row],[quarter average]]/Sheet2!$D$1 -> 0.93642066 | F30: =Table1[[#This Row],[RGDP]]/Table1[[#This Row],[seasonal index]] -> 2453808.5
B31: Q2 | C31: 2484417 | D31: 3371311 | E31: =Table1[[#This Row],[quarter average]]/Sheet2!$D$1 -> 1.0088808 | F31: =Table1[[#This Row],[RGDP]]/Table1[[#This Row],[seasonal index]] -> 2462547.5
B32: Q3 | C32: 2362773 | D32: 3210805.9 | E32: =Table1[[#This Row],[quarter average]]/Sheet2!$D$1 -> 0.96084893 | F32: =Table1[[#This Row],[RGDP]]/Table1[[#This Row],[seasonal index]] -> 2459047.3
B33: Q4 | C33: 2698252 | D33: 3655245.5 | E33: =Table1[[#This Row],[quarter average]]/Sheet2!$D$1 -> 1.0938496 | F33: =Table1[[#This Row],[RGDP]]/Table1[[#This Row],[seasonal index]] -> 2466748.7
A34: 2008 | B34: Q1 | C34: 2393607 | D34: 3129175.6 | E34: =Table1[[#This Row],[quarter average]]/Sheet2!$D$1 -> 0.93642066 | F34: =Table1[[#This Row],[RGDP]]/Table1[[#This Row],[seasonal index]] -> 2556123.6
B35: Q2 | C35: 2602999 | D35: 3371311 | E35: =Table1[[#This Row],[quarter average]]/Sheet2!$D$1 -> 1.0088808 | F35: =Table1[[#This Row],[RGDP]]/Table1[[#This Row],[seasonal index]] -> 2580085.7
B36: Q3 | C36: 2491196 | D36: 3210805.9 | E36: =Table1[[#This Row],[quarter average]]/Sheet2!$D$1 -> 0.96084893 | F36: =Table1[[#This Row],[RGDP]]/Table1[[#This Row],[seasonal index]] -> 2592703.1
B37: Q4 | C37: 2783075 | D37: 3655245.5 | E37: =Table1[[#This Row],[quarter average]]/Sheet2!$D$1 -> 1.0938496 | F37: =Table1[[#This Row],[RGDP]]/Table1[[#This Row],[seasonal index]] -> 2544294.1
A38: 2009 | B38: Q1 | C38: 2420350 | D38: 3129175.6 | E38: =Table1[[#This Row],[quarter average]]/Sheet2!$D$1 -> 0.93642066 | F38: =Table1[[#This Row],[RGDP]]/Table1[[#This Row],[seasonal index]] -> 2584682.4
B39: Q2 | C39: 2652251 | D39: 3371311 | E39: =Table1[[#This Row],[quarter average]]/Sheet2!$D$1 -> 1.0088808 | F39: =Table1[[#This Row],[RGDP]]/Table1[[#This Row],[seasonal index]] -> 2628904.1
B40: Q3 | C40: 2514311 | D40: 3210805.9 | E40: =Table1[[#This Row],[quarter average]]/Sheet2!$D$1 -> 0.96084893 | F40: =Table1[[#This Row],[RGDP]]/Table1[[#This Row],[seasonal index]] -> 2616760
...

Sheet Sheet2
A1: 1892885 | B1: =AVERAGE(A1:A25) -> 3655245.5 | C1: 1653296 | D1: =AVERAGE(C1:C100) -> 3341634.5
A2: 1956269 | C2: 1729789
A3: 2045575 | C3: 1709413
A4: 2162922 | C4: 1892885
A5: 2282020 | C5: 1693209
A6: 2389831 | C6: 1786322
A7: 2533516 | C7: 1762583
A8: 2698252 | C8: 1956269
A9: 2783075 | C9: 1758847
A10: 2832721 | C10: 1851705
A11: 3011152 | C11: 1809767
A12: 3132649 | C12: 2045575
A13: 3378370 | C13: 1840079
... A25: 6193631 | C25: 2164381
C26: 2325314
C27: 2217593
C28: 2533516
C29: 2297797
C30: 2484417
C31: 2362773
C32: 2698252
C33: 2393607
C34: 2602999
C35: 2491196
C36: 2783075
C37: 2420350
... C100: 6193631
